Traceback (most recent call last):
  File "/Users/whiletruelearn/miniforge3/envs/py310/lib/python3.10/site-packages/jupyter_cache/executors/utils.py", line 58, in single_nb_execution
    executenb(
  File "/Users/whiletruelearn/miniforge3/envs/py310/lib/python3.10/site-packages/nbclient/client.py", line 1314, in execute
    return NotebookClient(nb=nb, resources=resources, km=km, **kwargs).execute()
  File "/Users/whiletruelearn/miniforge3/envs/py310/lib/python3.10/site-packages/jupyter_core/utils/__init__.py", line 165, in wrapped
    return loop.run_until_complete(inner)
  File "/Users/whiletruelearn/miniforge3/envs/py310/lib/python3.10/asyncio/base_events.py", line 649, in run_until_complete
    return future.result()
  File "/Users/whiletruelearn/miniforge3/envs/py310/lib/python3.10/site-packages/nbclient/client.py", line 709, in async_execute
    await self.async_execute_cell(
  File "/Users/whiletruelearn/miniforge3/envs/py310/lib/python3.10/site-packages/nbclient/client.py", line 1062, in async_execute_cell
    await self._check_raise_for_error(cell, cell_index, exec_reply)
  File "/Users/whiletruelearn/miniforge3/envs/py310/lib/python3.10/site-packages/nbclient/client.py", line 918, in _check_raise_for_error
    raise CellExecutionError.from_cell_and_msg(cell, exec_reply_content)
nbclient.exceptions.CellExecutionError: An error occurred while executing the following cell:
------------------
dp[i] = some_function(dp[i-1], dp[i-2], ...)
------------------


[0;31m---------------------------------------------------------------------------[0m
[0;31mNameError[0m                                 Traceback (most recent call last)
Input [0;32mIn [1][0m, in [0;36m<cell line: 1>[0;34m()[0m
[0;32m----> 1[0m dp[i] [38;5;241m=[39m [43msome_function[49m(dp[i[38;5;241m-[39m[38;5;241m1[39m], dp[i[38;5;241m-[39m[38;5;241m2[39m], [38;5;241m.[39m[38;5;241m.[39m[38;5;241m.[39m)

[0;31mNameError[0m: name 'some_function' is not defined

